<?xml version="1.0" ?>
<robot name="pata_c" xmlns:xacro="http://ros.org/wiki/xacro">

<!--xacro:property name="motor_reduction"  value="${529.0/16}"/-->
<xacro:property name="motor_reduction"  value="${1}"/>
<xacro:property name="motor_max_effort" value="${3.5}"/>
<!--xacro:property name="motor_max_effort" value="${12}"/-->
<xacro:property name="motor_max_rev"    value="${1256.637/motor_reduction}"/>

<xacro:macro name="pata_c" params="name parent_link right *origin">

    <!--=====================================================================-->
    <!--        Definicion de las patas en C del robot hexapodo              -->
    <!--=====================================================================-->

    <!--*******************************************************************************************-->
    <!--Definicion del link de la pata-->
    <!--*******************************************************************************************-->

    <link name="${name}_pata_c_link">

        <!-- El origen de la pata varia en funcion de si se trata de una pata de la zona izquierda -->
        <!-- o de la zona derecha que se pasa como parametro -->

        <inertial>
            <origin xyz="${-42.439/1000} ${25/1000} ${-108.743/1000}" rpy="0 0 0"/>
            <mass value="0.057"/>
            <inertia ixx="${1038.176/(1e6)}"
                     ixy="${-218.169/(1e6)}"     iyy="${273.753/(1e6)}"
                     ixz="${59.956/(1e6)}"       iyz="${153.627/(1e6)}"      izz="${1217.746/(1e6)}"/>
        </inertial>

        <visual>
            <xacro:if value="${right == 1}">
                <origin xyz="0 0 0" rpy="${pi/2} 0 0"/>
            </xacro:if>
            <xacro:if value="${right == 0}">
                <origin xyz="0 0.05 0" rpy="${pi/2} 0 0"/>
            </xacro:if>
            <geometry>
                <mesh filename="package://hexapodo_description/meshes/pvc.stl" scale="0.001 0.001 0.001"/>
            </geometry>
            <material name="Grey">
                <color rgba="0.1 0.1 0.1 1"/>
            </material>
        </visual>

        <collision>
            <xacro:if value="${right == 1}">
                <origin xyz="0 0 0" rpy="${pi/2} 0 0"/>
            </xacro:if>
            <xacro:if value="${right == 0}">
                <origin xyz="0 0.05 0" rpy="${pi/2} 0 0"/>
            </xacro:if>
            <geometry>
                <mesh filename="package://hexapodo_description/meshes/pvc.stl" scale="0.001 0.001 0.001"/>
            </geometry>
            <surface>
              <friction>
                <ode>
                  <mu>100000.0</mu>
                  <mu2>100000.0</mu2>
                  <slip1>0.0</slip1>
                  <slip2>0.0</slip2>
                </ode>
              </friction>
            </surface>

        </collision>

    </link>

    <!--*******************************************************************************************-->
    <!--Definicion de la joint con el link padre-->
    <!--*******************************************************************************************-->

    <joint name="${name}_to_${parent_link}_joint" type="continuous">
        <xacro:insert_block name="origin"/>
        <parent link="${parent_link}"/>
        <child link="${name}_pata_c_link"/>
        <axis xyz="0 1 0"/>
        <limit effort="${motor_max_effort}" velocity="${motor_max_rev}"/> <!-- Nm rads/s -->
    </joint>

    <!--*******************************************************************************************-->
    <!--Definicion de la transmision de la pata-->
    <!--*******************************************************************************************-->

    <transmission name="${name}_transmission">
        <type>transmission_interface/SimpleTransmission</type>
        <joint name="${name}_to_${parent_link}_joint">
            <hardwareInterface>hardware_interface/EffortJointInterface</hardwareInterface>
        </joint>
        <actuator name="${name}_motor">
            <mechanicalReduction>${motor_reduction}</mechanicalReduction>
            <hardwareInterface>EffortJointInterface</hardwareInterface>
        </actuator>
    </transmission>

    <!--*******************************************************************************************-->
    <!--Definicion de las propiedades de gazebo-->
    <!--*******************************************************************************************-->


    <gazebo reference="${name}_pata_c_link">
        <mu1 value="100000.0"/>
        <mu2 value="100000.0"/>
        <kp  value="10000000.0" />
        <kd  value="1.0" />
        <fdir1 value="1 0 0"/>
        <material>Gazebo/Grey</material>
    </gazebo>

</xacro:macro>

</robot>
